<?xml version="1.0" encoding="utf-8"?>
<mujoco model="double_pendulum">

    <option gravity="0 0 -9.81">
    </option>

    <worldbody>

    <camera pos="-0.220 -4.372 1.228" xyaxes="0.999 -0.050 0.000 0.014 0.270 0.963"/>
    <camera name="fixed" pos="-0.220 -4.372 1.228" xyaxes="0.999 -0.050 0.000 0.014 0.270 0.963"/>


        <body name="base" pos="0 0 0">

            <body name="link1" pos="0 0 0">
                <joint name="joint1" type="hinge" axis="0 1 0" pos="0 0 0" limited="false"/>
                <geom name="link1_geom" type="capsule" fromto="0 0 0 0 0 1" size="0.03"/>

                <body name="link2" pos="0 0 0.5">
                    <joint name="joint2" type="slide" axis="0 0 1" pos="0 0 0" limited="true" range="0 0.5" />
                    <geom name="link2_geom" type="capsule" rgba="1 0 0 1"
                          fromto="0 0 0 0 0 +0.1" size="0.05"/>

                </body>

            </body>

        </body>
    </worldbody>


    <keyframe>
    <key name="keyframe_1" qpos="0.1 0" qvel="0 0" />
    </keyframe>


    <visual>
    <global offwidth="2560" offheight="1440"/>
    </visual>

    <actuator>
        <motor name="a1" joint="joint1" ctrlrange="-100 100" />
        <motor name="a2" joint="joint2" ctrlrange="-100 100" />
    </actuator>

</mujoco>
